<?xml version="1.0"?>
<robot name="reachy">

    <link name="world" />
    <joint name="world_joint" type="fixed">
        <origin rpy="0 0 0" xyz="0 0 0" />
        <parent link="world" />
        <child link="pedestal" />
    </joint>

<!-- Torso Link -->

<link name="pedestal"/>

<link name="torso">
    <inertial>
        <origin xyz="0.0 0.019 -0.009" rpy="0.0 0.0 0.0"/>
        <mass value="0.527"/>
        <inertia ixx="0.1" ixy="0.0" ixz="0.0" iyy="0.1" iyz="0.0" izz="0.1"/>
    </inertial>
    <visual name="">
        <origin xyz="0.0 0.0 0.0" rpy="0.0 0.0 0.0"/>
        <geometry>
            <mesh filename="package://reachy_description/meshes/torso.dae"/>
        </geometry>
    </visual>
    <collision>
        <origin xyz="0 0 -0.1" rpy="0 0.05 0" />
        <geometry>
            <box size="0.11 0.2 0.32" />
        </geometry>
    </collision>
</link>

<!-- Head Links -->

<link name="head">
    <inertial>
        <origin xyz="-0.009 -0.002 0.059" rpy="0.0 0.0 0.0"/> 
        <!-- <origin xyz="0.0 0.0 0.0" rpy="0.0 0.0 0.0"/> -->
        <mass value="0.237"/>
        <inertia ixx="0.1" ixy="0.0" ixz="0.0" iyy="0.1" iyz="0.0" izz="0.1"/>
    </inertial>
    <visual name="">
        <origin xyz="0.0 0.0 0.0" rpy="0.0 0.0 0.0"/>
        <geometry>
            <mesh filename="package://reachy_description/meshes/head.dae"/>
        </geometry>
    </visual>
    <collision>
        <origin xyz="-0.009 -0.002 0.059" rpy="0.0 0.0 0.0"/>
        <geometry>
            <cylinder length="0.15" radius="0.06" />
        </geometry>
    </collision>
</link>

<!--<link name="head_x" />

<link name="head_y" />

<link name="head_z" /> -->

<link name="l_antenna">
    <inertial>
        <origin xyz="-0.001 0.0 0.008" rpy="0.0 0.0 0.0"/>
        <mass value="0.004"/>
        <inertia ixx="0.1" ixy="0.0" ixz="0.0" iyy="0.1" iyz="0.0" izz="0.1"/>
    </inertial>
    <visual name="">
        <origin xyz="0.0 0.0 0.0" rpy="0.0 0.0 0.0"/>
        <geometry>
            <mesh filename="package://reachy_description/meshes/antenna.dae"/>
        </geometry>
    </visual>
    <collision>
        <origin xyz="0.1 0.0 0.1" rpy="0.0 0 0.0"/>
        <geometry>
            <cylinder length="0.09" radius="0.015" />
        </geometry>
    </collision>
</link>

<link name="r_antenna">
    <inertial>
        <origin xyz="-0.001 0.0 0.008" rpy="0.0 0.0 0.0"/>
        <mass value="0.004"/>
        <inertia ixx="0.1" ixy="0.0" ixz="0.0" iyy="0.1" iyz="0.0" izz="0.1"/>
    </inertial>
    <visual name="">
        <origin xyz="0.0 0.0 0.0" rpy="0.0 0.0 0.0"/>
        <geometry>
            <mesh filename="package://reachy_description/meshes/antenna.dae"/>
        </geometry>
    </visual>
    <collision>
        <origin xyz="0.0 0.0 0.0" rpy="0.0 0.0 0.0"/>
        <geometry>
            <cylinder length="0.09" radius="0.015" />
        </geometry>
    </collision>
</link>

<!-- Right Arm Links -->

<link name="r_shoulder">
    <inertial>
        <origin xyz="-0.016 0.036 0.0" rpy="1.57 1.57 0.0"/>
        <mass value="0.053"/>
        <inertia ixx="0.1" ixy="0.0" ixz="0.0" iyy="0.1" iyz="0.0" izz="0.1"/>
    </inertial>
    <visual name="">
        <origin xyz="0.0 0.04 0.0" rpy="1.57 1.57 0.0"/>
        <geometry>
            <mesh filename="package://reachy_description/meshes/shoulder.dae"/>
        </geometry>
    </visual>
    <collision>
        <origin xyz="0.0 0.04 0.0" rpy="1.57 1.57 0.0"/>
        <geometry>
            <cylinder length="0.09" radius="0.035" />
        </geometry>
    </collision>
</link>

<link name="r_shoulder_x">
    <inertial>
        <origin xyz="-0.0 0.0 -0.019" rpy="0.0 0.0 0.0"/>
        <mass value="0.158"/>
        <inertia ixx="0.1" ixy="0.0" ixz="0.0" iyy="0.1" iyz="0.0" izz="0.1"/>
    </inertial>
    <visual name="">
        <origin xyz="0.0 0.0 0.0" rpy="0.0 0.0 0.0"/>
        <geometry>
            <mesh filename="package://reachy_description/meshes/shoulder_x.dae"/>
        </geometry>
    </visual>
    <collision>
        <origin xyz="0 0 -0.02" rpy="0.0 0.0 0.0"/>
        <geometry>
            <cylinder length="0.04" radius="0.035" />
        </geometry>
    </collision>
</link>

<link name="r_upper_arm">
    <inertial>
        <origin xyz="-0.004 0.0 -0.1426" rpy="0.0 0.0 0.0"/>
        <mass value="0.430"/>
        <inertia ixx="0.1" ixy="0.0" ixz="0.0" iyy="0.1" iyz="0.0" izz="0.1"/>
    </inertial>
    <visual name="">
        <origin xyz="0.0 0.0 -0.0526" rpy="0.0 0.0 0.0"/>
        <geometry>
            <mesh filename="package://reachy_description/meshes/upper_arm.dae"/>
        </geometry>
    </visual>
    <collision>
        <origin xyz="0.0 0.0 -0.16" rpy="0.0 0.0 0.0"/>
        <geometry>
            <cylinder length="0.25" radius="0.04" />
        </geometry>
    </collision>
</link>

<link name="r_forearm">
    <inertial>
        <origin xyz="-0.008 0.0 -0.058" rpy="0.0 0.0 0.0"/>
        <mass value="0.162"/>
        <inertia ixx="0.1" ixy="0.0" ixz="0.0" iyy="0.1" iyz="0.0" izz="0.1"/>
    </inertial>
    <visual name="">
        <origin xyz="0.0 0.0 0.0" rpy="0.0 0.0 0.0"/>
        <geometry>
            <mesh filename="package://reachy_description/meshes/forearm.dae"/>
        </geometry>
    </visual>
    <collision>
        <origin xyz="0.0 0.0 -0.058" rpy="0.0 0.0 0.0"/>
        <geometry>
            <cylinder length="0.09" radius="0.04" />
        </geometry>
    </collision>
</link>

<link name="r_wrist">
    <inertial>
        <origin xyz="0.0 0.0 -0.193" rpy="0.0 0.0 0.0"/>
        <mass value="0.197"/>
        <inertia ixx="0.1" ixy="0.0" ixz="0.0" iyy="0.1" iyz="0.0" izz="0.1"/>
    </inertial>
    <visual name="">
        <origin xyz="0.0 0.0 -0.100" rpy="0.0 0.0 0.0"/>
        <geometry>
            <mesh filename="package://reachy_description/meshes/wrist.dae"/>
        </geometry>
    </visual>
    <collision>
        <origin xyz="0.0 0.0 -0.18" rpy="0.0 0.0 0.0"/>
        <geometry>
            <cylinder length="0.14" radius="0.035" />
        </geometry>
    </collision>
</link>

<link name="r_wrist2hand">
    <inertial>
        <origin xyz="0.0 0.0 0.014" rpy="0.0 0.0 0.0"/>
        <mass value="0.01"/>
        <inertia ixx="0.1" ixy="0.0" ixz="0.0" iyy="0.1" iyz="0.0" izz="0.1"/>
    </inertial>
    <visual name="">
        <origin xyz="0.0 0.0 0.0" rpy="0.0 0.0 0.0"/>
        <geometry>
            <mesh filename="package://reachy_description/meshes/wrist2hand.dae"/>
        </geometry>
    </visual>
    <collision>
        <origin xyz="0.0 0.0 -0.03" rpy="0.0 0.0 0.0"/>
        <geometry>
            <cylinder length="0.06" radius="0.03" />
        </geometry>
    </collision>
</link>

<link name="r_gripper_thumb">
    <inertial>
        <origin xyz="0.032 -0.008 0.0" rpy="0.0 1.57 0.0"/>
        <mass value="0.173"/>
        <inertia ixx="0.1" ixy="0.0" ixz="0.0" iyy="0.1" iyz="0.0" izz="0.1"/>
    </inertial>
    <visual name="">
        <origin xyz="0.0 0.0 0.0" rpy="0.0 1.57 0.0"/>
        <geometry>
            <mesh filename="package://reachy_description/meshes/r_gripper_thumb.dae"/>
        </geometry>
    </visual>
    <collision>
        <origin xyz="0.0 0.02 -0.06" rpy="0.0 1.57 0.0"/>
        <geometry>
            <box size="0.1 0.012 0.035" />
        </geometry>
    </collision>
</link>

<link name="r_gripper_finger">
    <inertial>
        <origin xyz="-0.005 -0.043 -0.0" rpy="0.0 1.57 0.0"/>
        <mass value="0.035"/>
        <inertia ixx="0.1" ixy="0.0" ixz="0.0" iyy="0.1" iyz="0.0" izz="0.1"/>
    </inertial>
    <visual name="">
        <origin xyz="0.0 0.0 0.0" rpy="0.0 1.57 0.0"/>
        <geometry>
            <mesh filename="package://reachy_description/meshes/r_gripper_finger.dae"/>
        </geometry>
    </visual>
    <collision>
        <origin xyz="0.0 -0.01 -0.02" rpy="0.0 1.57 0.0"/>
        <geometry>
            <box size="0.1 0.012 0.035" />
        </geometry>
    </collision>
</link>

<link name="right_tip"/>


<!-- Left Arm Links -->

<link name="l_shoulder">
    <inertial>
        <origin xyz="-0.016 0.044 0.0" rpy="-1.57 1.57 0.0"/>
        <mass value="0.053"/>
        <inertia ixx="0.1" ixy="0.0" ixz="0.0" iyy="0.1" iyz="0.0" izz="0.1"/>
    </inertial>
    <visual name="">
        <origin xyz="0.0 -0.04 0.0" rpy="-1.57 1.57 0.0"/>
        <geometry>
            <mesh filename="package://reachy_description/meshes/shoulder.dae"/>
        </geometry>
    </visual>
    <collision>
        <origin xyz="0.0 -0.04 0.0" rpy="-1.57 1.57 0.0"/>
        <geometry>
            <cylinder length="0.09" radius="0.035" />
        </geometry>
    </collision>
</link>

<link name="l_shoulder_x">
    <inertial>
        <origin xyz="0.0 0.0 -0.019" rpy="0.0 0.0 0.0"/>
        <mass value="0.158"/>
        <inertia ixx="0.1" ixy="0.0" ixz="0.0" iyy="0.1" iyz="0.0" izz="0.1"/>
    </inertial>
    <visual name="">
        <origin xyz="0.0 0.0 0.0" rpy="0.0 0.0 0.0"/>
        <geometry>
            <mesh filename="package://reachy_description/meshes/shoulder_x.dae"/>
        </geometry>
    </visual>
    <collision>
        <origin xyz="0 0 -0.02" rpy="0.0 0.0 0.0"/>
        <geometry>
            <cylinder length="0.04" radius="0.035" />
        </geometry>
    </collision>
</link>

<link name="l_upper_arm">
    <inertial>
        <origin xyz="-0.004 0.0 -0.1426" rpy="0.0 0.0 0.0"/>
        <mass value="0.430"/>
        <inertia ixx="0.1" ixy="0.0" ixz="0.0" iyy="0.1" iyz="0.0" izz="0.1"/>
    </inertial>
    <visual name="">
        <origin xyz="0.0 0.0 -0.0526" rpy="0.0 0.0 0.0"/>
        <geometry>
            <mesh filename="package://reachy_description/meshes/upper_arm.dae"/>
        </geometry>
    </visual>
    <collision>
        <origin xyz="0.0 0.0 -0.16" rpy="0.0 0.0 0.0"/>
        <geometry>
            <cylinder length="0.25" radius="0.04" />
        </geometry>
    </collision>
</link>

<link name="l_forearm">
    <inertial>
        <origin xyz="-0.008 0.0 -0.058" rpy="0.0 0.0 0.0"/>
        <mass value="0.162"/>
        <inertia ixx="0.1" ixy="0.0" ixz="0.0" iyy="0.1" iyz="0.0" izz="0.1"/>
    </inertial>
    <visual name="">
        <origin xyz="0.0 0.0 0.0" rpy="0.0 0.0 0.0"/>
        <geometry>
            <mesh filename="package://reachy_description/meshes/forearm.dae"/>
        </geometry>
    </visual>
    <collision>
        <origin xyz="0.0 0.0 -0.058" rpy="0.0 0.0 0.0"/>
        <geometry>
            <cylinder length="0.09" radius="0.04" />
        </geometry>
    </collision>
</link>

<link name="l_wrist">
    <inertial>
        <origin xyz="0.0 0.0 -0.193" rpy="0.0 0.0 0.0"/>
        <mass value="0.197"/>
        <inertia ixx="0.1" ixy="0.0" ixz="0.0" iyy="0.1" iyz="0.0" izz="0.1"/>
    </inertial>
    <visual name="">
        <origin xyz="0.0 0.0 -0.1" rpy="0.0 0.0 0.0"/>
        <geometry>
            <mesh filename="package://reachy_description/meshes/wrist.dae"/>
        </geometry>
    </visual>
    <collision>
        <origin xyz="0.0 0.0 -0.18" rpy="0.0 0.0 0.0"/>
        <geometry>
            <cylinder length="0.14" radius="0.035" />
        </geometry>
    </collision>
</link>

<link name="l_wrist2hand">
    <inertial>
        <origin xyz="0.0 0.0 0.014" rpy="0.0 0.0 0.0"/>
        <mass value="0.01"/>
        <inertia ixx="0.1" ixy="0.0" ixz="0.0" iyy="0.1" iyz="0.0" izz="0.1"/>
    </inertial>
    <visual name="">
        <origin xyz="0.0 0.0 0.0" rpy="0.0 0.0 0.0"/>
        <geometry>
            <mesh filename="package://reachy_description/meshes/wrist2hand.dae"/>
        </geometry>
    </visual>
    <collision>
        <origin xyz="0.0 0.0 -0.03" rpy="0.0 0.0 0.0"/>
        <geometry>
            <cylinder length="0.06" radius="0.03" />
        </geometry>
    </collision>
</link>

<link name="l_gripper_thumb">
    <inertial>
        <origin xyz="0.032 0.008 0.0" rpy="0.0 1.57 0.0"/>
        <mass value="0.173"/>
        <inertia ixx="0.1" ixy="0.0" ixz="0.0" iyy="0.1" iyz="0.0" izz="0.1"/>
    </inertial>
    <visual name="">
        <origin xyz="0.0 0.0 0.0" rpy="0.0 1.57 0.0"/>
        <geometry>
            <mesh filename="package://reachy_description/meshes/l_gripper_thumb.dae"/>
        </geometry>
    </visual>
    <collision>
        <origin xyz="0.0 -0.02 -0.06" rpy="0.0 1.57 0.0"/>
        <geometry>
            <box size="0.1 0.012 0.035" />
        </geometry>
    </collision>
</link>

<link name="l_gripper_finger">
    <inertial>
        <origin xyz="0.005 -0.043 0.0" rpy="0.0 1.57 0.0"/>
        <mass value="0.035"/>
        <inertia ixx="0.1" ixy="0.0" ixz="0.0" iyy="0.1" iyz="0.0" izz="0.1"/>
    </inertial>
    <visual name="">
        <origin xyz="0.0 0.0 0.0" rpy="0.0 1.57 0.0"/>
        <geometry>
            <mesh filename="package://reachy_description/meshes/l_gripper_finger.dae"/>
        </geometry>
    </visual>
    <collision>
        <origin xyz="0.0 0.01 -0.02" rpy="0.0 1.57 0.0"/>
        <geometry>
            <box size="0.1 0.012 0.035" />
        </geometry>
    </collision>
</link>

<link name="left_tip"/>

<!-- Head and Torso joints -->

<joint name="pedestal" type="fixed">
    <origin xyz="0 0 1" rpy="0 0 0" />
    <parent link="pedestal" />
    <child link="torso" />
</joint>

<joint name="r_antenna_yes" type="fixed">
    <origin xyz="-0.052 -0.057 0.086" rpy="-0.166 -1.054 1.11"/>
    <parent link="head"/> 
    <child link="r_antenna"/>
    <axis xyz="0 0 1"/>
   <limit lower="-2.618" upper="2.618" effort="10." velocity="0.0"/>
</joint>

<joint name="l_antenna_yes" type="fixed">
    <origin xyz="-0.052 0.057 0.086" rpy="0.166 -1.054 -1.11"/>
    <parent link="head"/> 
    <child link="l_antenna"/>
    <axis xyz="0 0 1"/>
   <limit lower="-2.618" upper="2.618" effort="10." velocity="0.0"/>
</joint>


<!-- Right Arm joint -->

<joint name="r_shoulder_pitch" type="revolute">
    <origin xyz="0.0 -0.19 0.0" rpy="0.0 0.0 0.0"/>
    <parent link="torso"/> 
    <child link="r_shoulder"/>
    <axis xyz="0 1 0"/>
   <limit lower="-2.618" upper="1.57" effort="10." velocity="0.0"/>
</joint>

<joint name="r_shoulder_roll" type="revolute">
    <origin xyz="0 0 0" rpy="0.0 0.0 0.0"/>
    <parent link="r_shoulder"/>
    <child link="r_shoulder_x"/>
    <axis xyz="1 0 0"/>
   <limit lower="-3.14" upper="0.174" effort="10." velocity="0.0"/>
</joint>

<joint name="r_arm_yaw" type="revolute">
    <origin xyz="0 0 0" rpy="0.0 0.0 0.0"/>
    <parent link="r_shoulder_x"/>
    <child link="r_upper_arm"/>
    <axis xyz="0 0 1"/>
   <limit lower="-1.57" upper="1.57" effort="10." velocity="0.0"/>
</joint>

<joint name="r_elbow_pitch" type="revolute">
    <origin xyz="0 0 -0.28" rpy="0.0 0.0 0.0"/>
    <parent link="r_upper_arm"/>
    <child link="r_forearm"/>
    <axis xyz="0 1 0"/>
   <limit lower="-2.182" upper="0" effort="10." velocity="0.0"/>
</joint>

<joint name="r_forearm_yaw" type="revolute">
    <origin xyz="0 0 0" rpy="0.0 0.0 0.0"/>
    <parent link="r_forearm"/>
    <child link="r_wrist"/>
    <axis xyz="0 0 1"/>
   <limit lower="-1.745" upper="1.745" effort="10." velocity="0.0"/>
</joint>

<joint name="r_wrist_pitch" type="revolute">
    <origin xyz="0 0 -0.25" rpy="0.0 0.0 0.0"/>
    <parent link="r_wrist"/>
    <child link="r_wrist2hand"/>
    <axis xyz="0 1 0"/>
   <limit lower="-0.785" upper="0.785" effort="10." velocity="0.0"/>
</joint>


<joint name="r_wrist_roll" type="revolute">
    <origin xyz="0 0 -0.0325" rpy="0.0 0.0 0.0"/>
    <parent link="r_wrist2hand"/>
    <child link="r_gripper_thumb"/>
    <axis xyz="1 0 0"/>
   <limit lower="-0.785" upper="0.785" effort="10." velocity="0.0"/>
</joint>

<joint name="r_gripper" type="revolute">
    <origin xyz="0.0 -0.037 -0.03998" rpy="0.0 0.0 0.0"/>
    <parent link="r_gripper_thumb"/>
    <child link="r_gripper_finger"/>
    <axis xyz="1 0 0"/>
   <limit lower="-1.2" upper="0.35" effort="10." velocity="0.0"/>
</joint>

<joint name="r_tip" type="fixed">
    <origin xyz="0 -0.012 -0.085" rpy="0 0 0" />
    <parent link="r_gripper_thumb" />
    <child link="right_tip" />
</joint>

<!-- Left arm joints -->
<joint name="l_shoulder_pitch" type="revolute">
    <origin xyz="0.0 0.19 0.0" rpy="0.0 0.0 0.0"/>
    <parent link="torso"/>
    <child link="l_shoulder"/>
    <axis xyz="0 1 0"/>
   <limit lower="-2.618" upper="1.57" effort="10." velocity="0.0"/>
</joint>

<joint name="l_shoulder_roll" type="revolute">
    <origin xyz="0 0 0" rpy="0.0 0.0 0.0"/>
    <parent link="l_shoulder"/>
    <child link="l_shoulder_x"/>
    <axis xyz="1 0 0"/>
   <limit lower="-0.174" upper="3.14" effort="10." velocity="0.0"/>
</joint>

<joint name="l_arm_yaw" type="revolute">
    <origin xyz="0 0 0" rpy="0.0 0.0 0.0"/>
    <parent link="l_shoulder_x"/>
    <child link="l_upper_arm"/>
    <axis xyz="0 0 1"/>
   <limit lower="-1.57" upper="1.57" effort="10." velocity="0.0"/> 
</joint>

<joint name="l_elbow_pitch" type="revolute">
    <origin xyz="0 0 -0.28" rpy="0.0 0.0 0.0"/>
    <parent link="l_upper_arm"/>
    <child link="l_forearm"/>
    <axis xyz="0 1 0"/>
   <limit lower="-2.182" upper="0" effort="10." velocity="0.0"/>
</joint>

<joint name="l_forearm_yaw" type="revolute">
    <origin xyz="0 0 0" rpy="0.0 0.0 0.0"/> 
    <parent link="l_forearm"/>
    <child link="l_wrist"/>
    <axis xyz="0 0 1"/>
   <limit lower="-1.745" upper="1.745" effort="10." velocity="0.0"/>
</joint>


<joint name="l_wrist_pitch" type="revolute">
    <origin xyz="0 0 -0.25" rpy="0.0 0.0 0.0"/>
    <parent link="l_wrist"/>
    <child link="l_wrist2hand"/>
    <axis xyz="0 1 0"/>
   <limit lower="-0.785" upper="0.785" effort="10." velocity="0.0"/>
</joint>


<joint name="l_wrist_roll" type="revolute">
    <origin xyz="0 0 -0.0325" rpy="0.0 0.0 0.0"/>
    <parent link="l_wrist2hand"/>
    <child link="l_gripper_thumb"/>
    <axis xyz="1 0 0"/>
   <limit lower="-0.785" upper="0.785" effort="10." velocity="0.0"/>
</joint>

<joint name="l_gripper" type="revolute">
    <origin xyz="0.0 0.037 -0.03998" rpy="0.0 0.0 0.0"/>
    <parent link="l_gripper_thumb"/>
    <child link="l_gripper_finger"/>
    <axis xyz="1 0 0"/>
   <limit lower="-0.35" upper="1.2" effort="10." velocity="0.0"/>
</joint>

<joint name="l_tip" type="fixed">
    <origin xyz="0 0.012 -0.085" rpy="0 0 0" />
    <parent link="l_gripper_thumb" />
    <child link="left_tip" />
</joint>

<!-- Head joint... -->


<!-- ...with a fixed joint -->

<!-- <joint name="torso2head" type="fixed">
    <origin xyz="0.0034 0.0 0.019" rpy="0 0 0" />
    <parent link="torso" />
    <child link="head" /> 
</joint> -->

<!-- ...with a ball orbita joint -->
<!--<joint name="orbita_roll" type="revolute">
    <origin xyz="0.0067 0.0 0.0478" rpy="0 0.174 0"/>
    <parent link="torso"/>
    <child link="head"/>
    <axis xyz="1 0 0"/>
   <limit lower="-0.8" upper="0.8" effort="10." velocity="0.0"/>
</joint>

<joint name="orbita_pitch" type="revolute">
    <origin xyz="0.0067 0.0 0.0478" rpy="0 0.174 0"/>
    <parent link="torso"/>
    <child link="head"/>
    <axis xyz="0 1 0"/>
   <limit lower="-0.8" upper="1.13" effort="10." velocity="0.0"/>
</joint>

<joint name="orbita_yaw" type="revolute">
    <origin xyz="0.0067 0.0 0.0478" rpy="0 0.174 0"/>
    <parent link="torso"/>
    <child link="head"/>
    <axis xyz="0 0 1"/>
   <limit lower="-2.79" upper="2.79" effort="10." velocity="0.0"/>
</joint>-->

<!--<joint name="orbita_fixed" type="fixed">
    <origin xyz="0 0 0" rpy="0.0 0.0 0.0"/>
    <parent link="head_z" />
    <child link="head" />
</joint> -->


<!-- Fixed Orbita Arms Visuals -->

<!--<joint name="orbita_top" type="fixed">
    <origin xyz="0.0067 0.0 0.0478" rpy="0 0.174 0"/>
    <parent link="torso"/>
    <child link="top_orbita_arm"/>
</joint>-->

<link name="top_orbita_arm">
    <inertial>
        <origin xyz="0.0 0.0 0.0" rpy="0.0 0.0 0.0"/>
        <mass value="0.01"/>
        <inertia ixx="0.01" ixy="0.01" ixz="0.01" iyy="0.0" iyz="0.0" izz="0.0"/>
    </inertial>
    <visual name="">
        <origin xyz="0.0 0.0 0.0" rpy="0.0 0.0 0.5236"/>
        <geometry>
            <mesh filename="package://reachy_description/meshes/orbita_arm.dae"/>
        </geometry>
    </visual>
    <collision>
        <origin xyz="0.0 0.0 0.0" rpy="0.0 0.0 0.0"/>
        <geometry>
            <cylinder length="0.0" radius="0.0" />
        </geometry>
    </collision>
</link>

<joint name="top2head" type="revolute">
    <origin xyz="0.0 0.0 0.047" rpy="0 0 0" />
    <parent link="top_orbita_arm" />
    <child link="head" />
    <axis xyz="1 0 0"/>
   <limit lower="-0.8" upper="0.8" effort="10." velocity="0.0"/>
</joint> 

<!--<joint name="orbita_middle" type="fixed">
    <origin xyz="0.0067 0.0 0.0478" rpy="0 0.174 0"/>
    <parent link="torso"/>
    <child link="middle_orbita_arm"/>
</joint>-->

<link name="middle_orbita_arm">
    <inertial>
        <origin xyz="0.0 0.0 0.0" rpy="0.0 0.0 0.0"/>
        <mass value="0.01"/>
        <inertia ixx="0.01" ixy="0.01" ixz="0.01" iyy="0.0" iyz="0.0" izz="0.0"/>
    </inertial>
    <visual name="">
        <origin xyz="0.0 0.0 0.0" rpy="0.0 0.0 2.618"/>
        <geometry>
            <mesh filename="package://reachy_description/meshes/orbita_arm.dae"/>
        </geometry>
    </visual>
    <collision>
        <origin xyz="0.0 0.0 0.0" rpy="0.0 0.0 0.0"/>
        <geometry>
            <cylinder length="0.0" radius="0.0" />
        </geometry>
    </collision>
</link>

<joint name="middle2top" type="revolute">
    <origin xyz="0.0 0.0 0.0" rpy="0 0 0" />
    <parent link="middle_orbita_arm" />
    <child link="top_orbita_arm" />
    <axis xyz="0 1 0"/>
   <limit lower="-0.8" upper="0.8" effort="10." velocity="0.0"/>
</joint> 

<joint name="orbita_bottom" type="fixed">
    <origin xyz="0.0067 0.0 0.0478" rpy="0 0.174 0"/>
    <parent link="torso"/>
    <child link="bottom_orbita_arm"/>
</joint>

<link name="bottom_orbita_arm">
    <inertial>
        <origin xyz="0.0 0.0 0.0" rpy="0.0 0.0 0.0"/>
        <mass value="0.01"/>
        <inertia ixx="0.01" ixy="0.01" ixz="0.01" iyy="0.0" iyz="0.0" izz="0.0"/>
    </inertial>
    <visual name="">
        <origin xyz="0.0 0.0 0.0" rpy="0.0 0.0 -1.57"/>
        <geometry>
            <mesh filename="package://reachy_description/meshes/orbita_arm.dae"/>
        </geometry>
    </visual>
    <collision>
        <origin xyz="0.0 0.0 0.0" rpy="0.0 0.0 0.0"/>
        <geometry>
            <cylinder length="0.0" radius="0.0" />
        </geometry>
    </collision>
</link>

<joint name="bottom2middle" type="revolute">
    <origin xyz="0.0 0.0 0.0" rpy="0 0 0" />
    <parent link="bottom_orbita_arm" />
    <child link="middle_orbita_arm" />
    <axis xyz="0 0 1"/>
   <limit lower="-0.8" upper="0.8" effort="10." velocity="0.0"/>
</joint> 

<!-- Cameras -->

<joint name="left_cam_fixed" type="fixed">
    <origin xyz="0.0033 0.03625 0.061" rpy="0.0 0.0 0.0"/>
    <parent link="head" />
    <child link="left_camera" />
</joint>

<link name="left_camera" />

<joint name="right_cam_fixed" type="fixed">
    <origin xyz="0.0033 -0.03625 0.061" rpy="0.0 0.0 0.0"/>
    <parent link="head" />
    <child link="right_camera" />
</joint>

<link name="right_camera" />

<transmission name="trans_r_shoulder_pitch">
        <type>transmission_interface/SimpleTransmission</type>
        <joint name="r_shoulder_pitch">
            <hardwareInterface>hardware_interface/EffortJointInterface</hardwareInterface>
        </joint>
        <actuator name="r_shoulder_pitch_motor">
            <hardwareInterface>hardware_interface/EffortJointInterface</hardwareInterface>
            <mechanicalReduction>1</mechanicalReduction>
        </actuator>
    </transmission>

    <transmission name="trans_r_shoulder_roll">
        <type>transmission_interface/SimpleTransmission</type>
        <joint name="r_shoulder_roll">
            <hardwareInterface>hardware_interface/EffortJointInterface</hardwareInterface>
        </joint>
        <actuator name="r_shoulder_roll_motor">
            <hardwareInterface>hardware_interface/EffortJointInterface</hardwareInterface>
            <mechanicalReduction>1</mechanicalReduction>
        </actuator>
    </transmission>

    <transmission name="trans_r_arm_yaw">
        <type>transmission_interface/SimpleTransmission</type>
        <joint name="r_arm_yaw">
            <hardwareInterface>hardware_interface/EffortJointInterface</hardwareInterface>
        </joint>
        <actuator name="r_arm_yaw_motor">
            <hardwareInterface>hardware_interface/EffortJointInterface</hardwareInterface>
            <mechanicalReduction>1</mechanicalReduction>
        </actuator>
    </transmission>

    <transmission name="trans_r_elbow_pitch">
        <type>transmission_interface/SimpleTransmission</type>
        <joint name="r_elbow_pitch">
            <hardwareInterface>hardware_interface/EffortJointInterface</hardwareInterface>
        </joint>
        <actuator name="r_elbow_pitch_motor">
            <hardwareInterface>hardware_interface/EffortJointInterface</hardwareInterface>
            <mechanicalReduction>1</mechanicalReduction>
        </actuator>
    </transmission>

    <transmission name="trans_r_forearm_yaw">
        <type>transmission_interface/SimpleTransmission</type>
        <joint name="r_forearm_yaw">
            <hardwareInterface>hardware_interface/EffortJointInterface</hardwareInterface>
        </joint>
        <actuator name="r_forearm_yaw_motor">
            <hardwareInterface>hardware_interface/EffortJointInterface</hardwareInterface>
            <mechanicalReduction>1</mechanicalReduction>
        </actuator>
    </transmission>

    <transmission name="trans_r_wrist_pitch">
        <type>transmission_interface/SimpleTransmission</type>
        <joint name="r_wrist_pitch">
            <hardwareInterface>hardware_interface/EffortJointInterface</hardwareInterface>
        </joint>
        <actuator name="r_wrist_pitch_motor">
            <hardwareInterface>hardware_interface/EffortJointInterface</hardwareInterface>
            <mechanicalReduction>1</mechanicalReduction>
        </actuator>
    </transmission>

    <transmission name="trans_r_wrist_roll">
        <type>transmission_interface/SimpleTransmission</type>
        <joint name="r_wrist_roll">
            <hardwareInterface>hardware_interface/EffortJointInterface</hardwareInterface>
        </joint>
        <actuator name="r_wrist_roll_motor">
            <hardwareInterface>hardware_interface/EffortJointInterface</hardwareInterface>
            <mechanicalReduction>1</mechanicalReduction>
        </actuator>
    </transmission>

    <transmission name="trans_l_shoulder_pitch">
        <type>transmission_interface/SimpleTransmission</type>
        <joint name="l_shoulder_pitch">
            <hardwareInterface>hardware_interface/EffortJointInterface</hardwareInterface>
        </joint>
        <actuator name="l_shoulder_pitch_motor">
            <hardwareInterface>hardware_interface/EffortJointInterface</hardwareInterface>
            <mechanicalReduction>1</mechanicalReduction>
        </actuator>
    </transmission>

    <transmission name="trans_l_shoulder_roll">
        <type>transmission_interface/SimpleTransmission</type>
        <joint name="l_shoulder_roll">
            <hardwareInterface>hardware_interface/EffortJointInterface</hardwareInterface>
        </joint>
        <actuator name="l_shoulder_roll_motor">
            <hardwareInterface>hardware_interface/EffortJointInterface</hardwareInterface>
            <mechanicalReduction>1</mechanicalReduction>
        </actuator>
    </transmission>

    <transmission name="trans_l_arm_yaw">
        <type>transmission_interface/SimpleTransmission</type>
        <joint name="l_arm_yaw">
            <hardwareInterface>hardware_interface/EffortJointInterface</hardwareInterface>
        </joint>
        <actuator name="l_arm_yaw_motor">
            <hardwareInterface>hardware_interface/EffortJointInterface</hardwareInterface>
            <mechanicalReduction>1</mechanicalReduction>
        </actuator>
    </transmission>

    <transmission name="trans_l_elbow_pitch">
        <type>transmission_interface/SimpleTransmission</type>
        <joint name="l_elbow_pitch">
            <hardwareInterface>hardware_interface/EffortJointInterface</hardwareInterface>
        </joint>
        <actuator name="l_elbow_pitch_motor">
            <hardwareInterface>hardware_interface/EffortJointInterface</hardwareInterface>
            <mechanicalReduction>1</mechanicalReduction>
        </actuator>
    </transmission>

    <transmission name="trans_l_forearm_yaw">
        <type>transmission_interface/SimpleTransmission</type>
        <joint name="l_forearm_yaw">
            <hardwareInterface>hardware_interface/EffortJointInterface</hardwareInterface>
        </joint>
        <actuator name="l_forearm_yaw_motor">
            <hardwareInterface>hardware_interface/EffortJointInterface</hardwareInterface>
            <mechanicalReduction>1</mechanicalReduction>
        </actuator>
    </transmission>

    <transmission name="trans_l_wrist_pitch">
        <type>transmission_interface/SimpleTransmission</type>
        <joint name="l_wrist_pitch">
            <hardwareInterface>hardware_interface/EffortJointInterface</hardwareInterface>
        </joint>
        <actuator name="l_wrist_pitch_motor">
            <hardwareInterface>hardware_interface/EffortJointInterface</hardwareInterface>
            <mechanicalReduction>1</mechanicalReduction>
        </actuator>
    </transmission>

    <transmission name="trans_l_wrist_roll">
        <type>transmission_interface/SimpleTransmission</type>
        <joint name="l_wrist_roll">
            <hardwareInterface>hardware_interface/EffortJointInterface</hardwareInterface>
        </joint>
        <actuator name="l_wrist_roll_motor">
            <hardwareInterface>hardware_interface/EffortJointInterface</hardwareInterface>
            <mechanicalReduction>1</mechanicalReduction>
        </actuator>
    </transmission>

    <transmission name="trans_l_gripper">
        <type>transmission_interface/SimpleTransmission</type>
        <joint name="l_gripper">
            <hardwareInterface>hardware_interface/EffortJointInterface</hardwareInterface>
        </joint>
        <actuator name="l_gripper_motor">
            <hardwareInterface>hardware_interface/EffortJointInterface</hardwareInterface>
            <mechanicalReduction>1</mechanicalReduction>
        </actuator>
    </transmission>

    <transmission name="trans_r_gripper">
        <type>transmission_interface/SimpleTransmission</type>
        <joint name="r_gripper">
            <hardwareInterface>hardware_interface/EffortJointInterface</hardwareInterface>
        </joint>
        <actuator name="r_gripper_motor">
            <hardwareInterface>hardware_interface/EffortJointInterface</hardwareInterface>
            <mechanicalReduction>1</mechanicalReduction>
        </actuator>
    </transmission>

    <!--<transmission name="trans_r_antenna">
        <type>transmission_interface/SimpleTransmission</type>
        <joint name="r_antenna_yes">
            <hardwareInterface>hardware_interface/EffortJointInterface</hardwareInterface>
        </joint>
        <actuator name="r_antenna_motor">
            <hardwareInterface>hardware_interface/EffortJointInterface</hardwareInterface>
            <mechanicalReduction>1</mechanicalReduction>
        </actuator>
    </transmission>

    <transmission name="trans_l_antenna">
        <type>transmission_interface/SimpleTransmission</type>
        <joint name="l_antenna_yes">
            <hardwareInterface>hardware_interface/EffortJointInterface</hardwareInterface>
        </joint>
        <actuator name="l_antenna_motor">
            <hardwareInterface>hardware_interface/EffortJointInterface</hardwareInterface>
            <mechanicalReduction>1</mechanicalReduction>
        </actuator>
    </transmission>-->

    <transmission name="trans_orbita_roll">
        <type>transmission_interface/SimpleTransmission</type>
        <joint name="top2head">
            <hardwareInterface>hardware_interface/EffortJointInterface</hardwareInterface>
        </joint>
        <actuator name="orbita_roll_motor">
            <hardwareInterface>hardware_interface/EffortJointInterface</hardwareInterface>
            <mechanicalReduction>1</mechanicalReduction>
        </actuator>
    </transmission>

    <transmission name="trans_orbita_pitch">
        <type>transmission_interface/SimpleTransmission</type>
        <joint name="middle2top">
            <hardwareInterface>hardware_interface/EffortJointInterface</hardwareInterface>
        </joint>
        <actuator name="orbita_pitch_motor">
            <hardwareInterface>hardware_interface/EffortJointInterface</hardwareInterface>
            <mechanicalReduction>1</mechanicalReduction>
        </actuator>
    </transmission>

    <transmission name="trans_orbita_yaw">
        <type>transmission_interface/SimpleTransmission</type>
        <joint name="bottom2middle">
            <hardwareInterface>hardware_interface/EffortJointInterface</hardwareInterface>
        </joint>
        <actuator name="orbita_yaw_motor">
            <hardwareInterface>hardware_interface/EffortJointInterface</hardwareInterface>
            <mechanicalReduction>1</mechanicalReduction>
        </actuator>
    </transmission> 



    <gazebo>
        <plugin name="gazebo_ros_control" filename="libgazebo_ros_control.so">
            <robotNamespace>/reachy</robotNamespace>
        </plugin>
    </gazebo>



</robot>
